# #8. Promises

### Introducation to Async

---

- 자바스크립트의 **비동기성**

  : 순차적으로 처리되는 것이 아니라 한꺼번에 실행됨

```javascript
const hello = fetch("google.com")

console.log("something")
console.log(hello)

// something
// Promise {<rejected>: TypeError: Failed to fetch ...
```



### Promise

---

- **Promise**

  : 비동기 작업이 맞이할 미래의 완료 또는 실패와 그 결과 값을 나타냄

```javascript
const promiseExample = new Promise((resolve, reject) => {
    
})

console.log(promiseExample) // Promise {<pending>}
// promise가 아직 pending 중(끝나지 않음을 뜻함)
// 자바스크립트는 promise가 끝나길 기다림
```

*promise resolve*

```javascript
const promiseExample = new Promise((resolve, reject) => {
    setTimeout(resolve, 3000, "ok!") 
})

console.log(promiseExample)

setInterval(console.log, 1000, promiseExample)

// Promise {<pending>}
// Promise {<pending>}
// Promise {<pending>}
// Promise {<fulfilled>: "ok!"}
// Promise {<fulfilled>: "ok!"}
// ....
```

promise의 핵심은 아직 모르는 value와 함께 작업할 수 있다는 것



- Using Promises (Then)

  :자바스크립트에 promise가 끝난 이후 명령을 전달하기 위해선 값을 돌려달라고 명령어(then)를 지시 해야함

```javascript
const promiseExample = new Promise((resolve, reject) => {
    setTimeout(resolve, 3000, "ok!") 
})

promiseExample.then(value => console.log(value)) 
// 3초 뒤 ok! 출력
```

*reject: promise의 문제가 생기면(reject) 문제를 catch하면 됨*

```javascript
const promiseExample = new Promise((resolve, reject) => {
    setTimeout(reject, 3000, "no!") 
})

promiseExample.then(value => console.log(value)) 
// 3초 뒤 error

promiseExample.then(result => console.log(result)).catch(error => console.log(error))
// 3초 뒤 no!

// promise가 resolve 되면 then이 실행되고 reject가 되면 catch가 실행됨
```



- Chaning Promises

```javascript
const promiseExample = new Promise((resolve, reject) => {
    resolve(2)
})

promiseExample.then(number => console.log(number)) // 2

// 결과 값이 여러개 나와야 하는 경우(여러개의 promises)
// chaning 
promiseExample.then(number => {
    console.log(2 * 2)
    return number * 2 
}).then(otherNumber => {
    console.log(otherNumber * 2)
}) // then을 쓰기 위해선 return 값이 존재해야 함

// 4
// 8
```

*catch*

```javascript
const promiseExample = new Promise((resolve, reject) => {
    resolve(2)
})

const timesTwo = (number) => number * 2

promiseExample
	.then(timesTwo)
	.then(timesTwo)
	.then(timesTwo)
	.then(timesTwo)
	.then(timesTwo)
	.then(lastNumber => console.log("lastNumber")) // 64


// error 발생 시 (catch)
promiseExample
	.then(timesTwo)
	.then(timesTwo)
	.then(timesTwo)
	.then(timesTwo)
	.then() => {
    	throw Error("Something is wrong")
	}
	.then(lastNumber => console.log("lastNumber"))
	.catch(error => console.log(error))
// error: Something is wrong
```



- Promise.all

  : 주어진 모든 Promise를 실행한 후 진행되는 하나의 Promise를 반환

  *ex) 여러개의 API에서 값을 불러와야 할 때 Promise.all 을 사용*

  모든 Promise가 Resolve되면 마지막 Promise를 return 값으로 줌

```javascript
const p1 = new Promise((resolve) => {
    setTimeout(resolve, 5000, "First")
})

const p2 = new Promise((resolve) => {
    setTimeout(resolve, 1000, "Second")
})

const p3 = new Promise((resolve) => {
    setTimeout(resolve, 3000, "Third")
})

const motherPromise = Promise.all([p1, p2, p3])

motherPromise.then(values => console.log(values)) 
// ["First", "Second", "Third"]


// reject인 경우
// promise.all에만 catch 써주면 됨 (하나라도 reject인 경우 error)
const p1 = new Promise((resolve) => {
    setTimeout(resolve, 5000, "First")
})

const p2 = new Promise((reject) => {
    setTimeout(reject, 1000, "I hate JS")
})

const p3 = new Promise((resolve) => {
    setTimeout(resolve, 3000, "Third")
})

const motherPromise = Promise.all([p1, p2, p3])

motherPromise
    .then(values => console.log(values)) 
	.catch(err => console.log(err))
// I hate JS
```



- Promise.race

  : 여러개의 Promise 중 하나라도 resolve거나 reject 되면 return

  여러 Promise 중 빠르게 실행되는 것에 초점을 둔 함수

  하나의 promise가 성공하거나 reject가 발생하지 않으면 resolve

```javascript
const p1 = new Promise((resolve) => {
    setTimeout(resolve, 10000, "First")
})

const p2 = new Promise((reject) => {
    setTimeout(reject, 5000, "I hate JS")
})

const p3 = new Promise((resolve) => {
    setTimeout(resolve, 3000, "Third")
})

motherPromise
	.then(values => console.log(values))
	.catch(err => console.log(err))
// Third
```



- finally

  :  Promise 동작이 끝났을 때 실행되는 함수

```javascript
/* resolve */
const p1 = new Promise((resolve) => {
    setTimeout(resolve, 10000, "First")
})
	.then(value => console.log(value))
	.finally(() => console.log("Im done"))
// First
// Im done

/* reject */
const p1 = new Promise((reject) => {
    setTimeout(reject, 10000, "fail")
})
	.then(value => console.log(value))
	.catch(e => console.log(e))
	.finally(() => console.log("Im done"))
// fail
// Im done
```



- fetch

```javascript
fetch("https://google.com")
    .then(response => console.log(response))
    .catch(e => console.log(`X ${e}`))
// X TypeError: Failed to fetch
```

*API 요청을 하면 API는 response를 줌 -> response를 텍스트로 변환하는 것을 시행 -> Promise를 줌 -> then을 사용해서 return*

```javascript
fetch("https://...")
	.then(response => response.text())
	.then(json => console.log(json))
	.catch(e => console.log(`X ${e}`))

// <!DOCTYPE html>
// <html lang="en">
// 	<head>
// ...
```

